<?xml version="1.0"?>
<robot xmlns:xacro="http://ros.org/wiki/xacro">

  <!-- ======================== FRONT LEFT (FL) ======================== -->
  <link name="FL_SHOULDER">
    <inertial>
      <origin xyz="0.051772 0.021258 -0.000161" rpy="0 0 0" />
      <mass value="1.276" />
      <inertia ixx="0.001862" ixy="0.000034" ixz="0.000001" iyy="0.001745" iyz="0.000000" izz="0.001887" />
    </inertial>
    <visual>
      <origin xyz="0 0 0" rpy="0 0 0" />
      <geometry><mesh filename="package://quadruped_description/meshes/FL_SHOULDER.dae" /></geometry>
      <material name="black"/>
    </visual>
    <collision>
      <origin xyz="0.054 0 0" rpy="0 0 0" />
      <geometry><box size="0.1 0.1 0.1" /></geometry>
    </collision>
  </link>
  <joint name="FL_HAA" type="revolute">
    <origin xyz="0.2635 0.12291 0" rpy="0 0 0" />
    <parent link="base" />
    <child link="FL_SHOULDER" />
    <axis xyz="1 0 0" />
    <dynamics damping="0.7" friction="0.0" />
    <limit lower="-3.14" upper="3.14" effort="85.0" velocity="16.75" />
  </joint>

  <link name="FL_UPPER_LEG">
    <inertial>
      <origin xyz="0.000009 0.025634 -0.165001" rpy="0 0 0" />
      <mass value="1.367" />
      <inertia ixx="0.016273" ixy="-0.000000" ixz="0.000012" iyy="0.016691" iyz="0.000130" izz="0.001167" />
    </inertial>
    <visual>
      <origin xyz="0 0 0" rpy="0 0 0" />
      <geometry><mesh filename="package://quadruped_description/meshes/FL_UPPER_LEG.dae" /></geometry>
      <material name="black2"/>
    </visual>
    <collision>
      <origin xyz="0 0.032 -0.1232" rpy="0 0 0" />
      <geometry><box size="0.1 0.05 0.3" /></geometry>
    </collision>
  </link>
  <joint name="FL_HFE" type="revolute">
    <origin xyz="0.053259 0.061836 -0.0001687" rpy="0 0 0" />
    <parent link="FL_SHOULDER" />
    <child link="FL_UPPER_LEG" />
    <axis xyz="0 1 0" />
    <dynamics damping="0.9" friction="0.0" />
    <limit lower="-3.14" upper="3.14" effort="80.0" velocity="23.04" />
  </joint>

  <link name="FL_LOWER_LEG">
    <inertial>
      <origin xyz="-0.041308 0.034919 -0.047598" rpy="0 0 0" />
      <mass value="0.759" />
      <inertia ixx="0.007966" ixy="-0.000009" ixz="0.001312" iyy="0.009247" iyz="-0.000002" izz="0.001638" />
    </inertial>
    <visual>
      <origin xyz="0 0 0" rpy="0 0 0" />
      <geometry><mesh filename="package://quadruped_description/meshes/FL_LOWER_LEG.dae" /></geometry>
      <material name="black3"/>
    </visual>
    <collision>
      <origin xyz="-0.0772 0.035 -0.09" rpy="0 0 0" />
      <geometry><cylinder length="0.3" radius="0.02"/></geometry>
    </collision>
  </link>
  <joint name="FL_KFE" type="revolute">
    <origin xyz="0 0.0465 -0.2465" rpy="0 0 0" />
    <parent link="FL_UPPER_LEG" />
    <child link="FL_LOWER_LEG" />
    <axis xyz="0 1 0" />
    <dynamics damping="0.9" friction="0.0" />
    <limit lower="-3.14" upper="3.14" effort="80.0" velocity="23.04" />
  </joint>

  <link name="FL_FOOT">
    <inertial>
      <origin xyz="0.035896 -0.000081 0.186367" rpy="0 0 0" />
      <mass value="0.01" />
      <inertia ixx="0.007966" ixy="-0.000009" ixz="0.001312" iyy="0.009247" iyz="-0.000002" izz="0.001638" />
    </inertial>
    <visual>
      <origin xyz="0 0 0" rpy="0 0 0" />
      <geometry><mesh filename="package://quadruped_description/meshes/FL_FOOT.dae" /></geometry>
      <material name="red"/>
    </visual>
    <collision>
      <origin xyz="0 0 -0.02" rpy="0 0 0" />
      <geometry><sphere radius="0.0267" /></geometry>
    </collision>
  </link>
  <joint name="FL_FOOT_JOINT" type="fixed">
    <origin xyz="-0.077204 0.035 -0.23396" rpy="0 0 0" />
    <parent link="FL_LOWER_LEG" />
    <child link="FL_FOOT" />
  </joint>

  <!-- ======================== FRONT RIGHT (FR) ======================== -->
  <link name="FR_SHOULDER">
    <inertial>
      <origin xyz="0.051772 -0.021258 -0.000161" rpy="0 0 0" />
      <mass value="1.276" />
      <inertia ixx="0.001862" ixy="-0.000034" ixz="0.000001" iyy="0.001745" iyz="-0.000000" izz="0.001887" />
    </inertial>
    <visual>
      <origin xyz="0 0 0" rpy="0 0 0" />
      <geometry><mesh filename="package://quadruped_description/meshes/FR_SHOULDER.dae" /></geometry>
      <material name="black"/>
    </visual>
    <collision>
      <origin xyz="0.054 0 0" rpy="0 0 0" />
      <geometry><box size="0.1 0.1 0.1" /></geometry>
    </collision>
  </link>
  <joint name="FR_HAA" type="revolute">
    <origin xyz="0.2635 -0.12291 0" rpy="0 0 0" />
    <parent link="base" />
    <child link="FR_SHOULDER" />
    <axis xyz="1 0 0" />
    <dynamics damping="0.7" friction="0.0" />
    <limit lower="-3.14" upper="3.14" effort="85.0" velocity="16.75" />
  </joint>

  <link name="FR_UPPER_LEG">
    <inertial>
      <origin xyz="0.000009 -0.025634 -0.165001" rpy="0 0 0" />
      <mass value="1.367" />
      <inertia ixx="0.016273" ixy="0.000000" ixz="0.000012" iyy="0.016691" iyz="-0.000130" izz="0.001167" />
    </inertial>
    <visual>
      <origin xyz="0 0 0" rpy="0 0 0" />
      <geometry><mesh filename="package://quadruped_description/meshes/FR_UPPER_LEG.dae" /></geometry>
      <material name="black2"/>
    </visual>
    <collision>
      <origin xyz="0 -0.028 -0.1232" rpy="0 0 0" />
      <geometry><box size="0.1 0.05 0.3" /></geometry>
    </collision>
  </link>
  <joint name="FR_HFE" type="revolute">
    <origin xyz="0.053259 -0.061836 0.0000999" rpy="0 0 0" />
    <parent link="FR_SHOULDER" />
    <child link="FR_UPPER_LEG" />
    <axis xyz="0 1 0" />
    <dynamics damping="0.9" friction="0.0" />
    <limit lower="-3.14" upper="3.14" effort="80.0" velocity="23.04" />
  </joint>

  <link name="FR_LOWER_LEG">
    <inertial>
      <origin xyz="-0.041308 -0.034919 -0.047598" rpy="0 0 0" />
      <mass value="0.759" />
      <inertia ixx="0.007966" ixy="0.000009" ixz="0.001312" iyy="0.009247" iyz="0.000002" izz="0.001638" />
    </inertial>
    <visual>
      <origin xyz="0 0 0" rpy="0 0 0" />
      <geometry><mesh filename="package://quadruped_description/meshes/FR_LOWER_LEG.dae" /></geometry>
      <material name="black3"/>
    </visual>
    <collision>
      <origin xyz="-0.0772 -0.035 -0.09" rpy="0 0 0" />
      <geometry><cylinder length="0.3" radius="0.02"/></geometry>
    </collision>
  </link>
  <joint name="FR_KFE" type="revolute">
    <origin xyz="0 -0.0465 -0.2465" rpy="0 0 0" />
    <parent link="FR_UPPER_LEG" />
    <child link="FR_LOWER_LEG" />
    <axis xyz="0 1 0" />
    <dynamics damping="0.9" friction="0.0" />
    <limit lower="-3.14" upper="3.14" effort="80.0" velocity="23.04" />
  </joint>

  <link name="FR_FOOT">
    <inertial>
      <origin xyz="0.035896 0.000081 0.186367" rpy="0 0 0" />
      <mass value="0.01" />
      <inertia ixx="0.007966" ixy="0.000009" ixz="0.001312" iyy="0.009247" iyz="0.000002" izz="0.001638" />
    </inertial>
    <visual>
      <origin xyz="0 0 0" rpy="0 0 0" />
      <geometry><mesh filename="package://quadruped_description/meshes/FR_FOOT.dae" /></geometry>
      <material name="red"/>
    </visual>
    <collision>
      <origin xyz="0 0 -0.02" rpy="0 0 0" />
      <geometry><sphere radius="0.0267" /></geometry>
    </collision>
  </link>
  <joint name="FR_FOOT_JOINT" type="fixed">
    <origin xyz="-0.07715 -0.035 -0.23396" rpy="0 0 0" />
    <parent link="FR_LOWER_LEG" />
    <child link="FR_FOOT" />
  </joint>

  <!-- ======================== HIND LEFT (HL) ======================== -->
  <link name="HL_SHOULDER">
    <inertial>
      <origin xyz="-0.051779 0.021258 0.000042" rpy="0 0 0" />
      <mass value="1.276" />
      <inertia ixx="0.001862" ixy="-0.000034" ixz="-0.000000" iyy="0.001745" iyz="-0.000000" izz="0.001886" />
    </inertial>
    <visual>
      <origin xyz="0 0 0" rpy="0 0 0" />
      <geometry><mesh filename="package://quadruped_description/meshes/HL_SHOULDER.dae" /></geometry>
      <material name="black"/>
    </visual>
    <collision>
      <origin xyz="-0.054 0 0" rpy="0 0 0" />
      <geometry><box size="0.1 0.1 0.1" /></geometry>
    </collision>
  </link>
  <joint name="HL_HAA" type="revolute">
    <origin xyz="-0.2635 0.12291 0" rpy="0 0 0" />
    <parent link="base" />
    <child link="HL_SHOULDER" />
    <axis xyz="1 0 0" />
    <dynamics damping="0.7" friction="0.0" />
    <limit lower="-3.14" upper="3.14" effort="85.0" velocity="16.75" />
  </joint>

  <link name="HL_UPPER_LEG">
    <inertial>
      <origin xyz="0.000003 0.025470 -0.134787" rpy="0 0 0" />
      <mass value="1.315" />
      <inertia ixx="0.011053" ixy="-0.000000" ixz="0.000013" iyy="0.011463" iyz="0.000105" izz="0.001146" />
    </inertial>
    <visual>
      <origin xyz="0 0 0" rpy="0 0 0" />
      <geometry><mesh filename="package://quadruped_description/meshes/HL_UPPER_LEG.dae" /></geometry>
      <material name="black1"/>
    </visual>
    <collision>
      <origin xyz="0 0.028 -0.1005" rpy="0 0 0" />
      <geometry><box size="0.08 0.05 0.26" /></geometry>
    </collision>
  </link>
  <joint name="HL_HFE" type="revolute">
    <origin xyz="-0.053259 0.061836 0.0000999" rpy="0 0 0" />
    <parent link="HL_SHOULDER" />
    <child link="HL_UPPER_LEG" />
    <axis xyz="0 1 0" />
    <dynamics damping="0.9" friction="0.0" />
    <limit lower="-3.14" upper="3.14" effort="85.0" velocity="16.75" />
  </joint>

  <link name="HL_LOWER_LEG">
    <inertial>
      <origin xyz="0.000005 0.041724 -0.160773" rpy="0 0 0" />
      <mass value="1.406" />
      <inertia ixx="0.017322" ixy="-0.000000" ixz="0.000013" iyy="0.017702" iyz="-0.000074" izz="0.001218" />
    </inertial>
    <visual>
      <origin xyz="0 0 0" rpy="0 0 0" />
      <geometry><mesh filename="package://quadruped_description/meshes/HL_LOWER_LEG.dae" /></geometry>
      <material name="black2"/>
    </visual>
    <collision>
      <origin xyz="0 0.045 -0.1233" rpy="0 0 0" />
      <geometry><box size="0.06 0.05 0.35" /></geometry>
    </collision>
  </link>
  <joint name="HL_KFE" type="revolute">
    <origin xyz="0 0.0465 -0.201" rpy="0 0 0" />
    <parent link="HL_UPPER_LEG" />
    <child link="HL_LOWER_LEG" />
    <axis xyz="0 1 0" />
    <dynamics damping="0.9" friction="0.0" />
    <limit lower="-3.14" upper="3.14" effort="80.0" velocity="23.04" />
  </joint>

  <link name="HL_SHANK">
    <inertial>
      <origin xyz="-0.040122 0.034916 -0.027409" rpy="0 0 0" />
      <mass value="0.734" />
      <inertia ixx="0.003597" ixy="-0.000009" ixz="0.000762" iyy="0.004846" iyz="-0.000001" izz="0.001602" />
    </inertial>
    <visual>
      <origin xyz="0 0 0" rpy="0 0 0" />
      <geometry><mesh filename="package://quadruped_description/meshes/HL_SHANK.dae" /></geometry>
      <material name="black3"/>
    </visual>
    <collision>
      <origin xyz="-0.0772 0.035 -0.045" rpy="0 0 0" />
      <geometry><cylinder length="0.21" radius="0.02"/></geometry>
    </collision>
  </link>
  <joint name="HL_AFE" type="revolute">
    <origin xyz="0 0.0635 -0.2465" rpy="0 0 0" />
    <parent link="HL_LOWER_LEG" />
    <child link="HL_SHANK" />
    <axis xyz="0 1 0" />
    <dynamics damping="0.9" friction="0.0" />
    <limit lower="-3.14" upper="3.14" effort="80.0" velocity="23.04" />
  </joint>

  <link name="HL_FOOT">
    <inertial>
      <origin xyz="0.037082 -0.000084 0.116555" rpy="0 0 0" />
      <mass value="0.01" />
      <inertia ixx="0.003597" ixy="-0.000009" ixz="0.000762" iyy="0.004846" iyz="-0.000001" izz="0.001602" />
    </inertial>
    <visual>
      <origin xyz="0 0 0" rpy="0 0 0" />
      <geometry><mesh filename="package://quadruped_description/meshes/HL_FOOT.dae" /></geometry>
      <material name="red"/>
    </visual>
    <collision>
      <origin xyz="0 0 -0.02" rpy="0 0 0" />
      <geometry><sphere radius="0.0267" /></geometry>
    </collision>
  </link>
  <joint name="HL_FOOT_JOINT" type="fixed">
    <origin xyz="-0.077204 0.035 -0.14396" rpy="0 0 0" />
    <parent link="HL_SHANK" />
    <child link="HL_FOOT" />
  </joint>

  <!-- ======================== HIND RIGHT (HR) ======================== -->
  <link name="HR_SHOULDER">
    <inertial>
      <origin xyz="-0.051779 -0.021258 0.000042" rpy="0 0 0" />
      <mass value="1.276" />
      <inertia ixx="0.001862" ixy="0.000034" ixz="-0.000000" iyy="0.001745" iyz="0.000000" izz="0.001886" />
    </inertial>
    <visual>
      <origin xyz="0 0 0" rpy="0 0 0" />
      <geometry><mesh filename="package://quadruped_description/meshes/HR_SHOULDER.dae" /></geometry>
      <material name="black"/>
    </visual>
    <collision>
      <origin xyz="-0.054 0 0" rpy="0 0 0" />
      <geometry><box size="0.1 0.1 0.1" /></geometry>
    </collision>
  </link>
  <joint name="HR_HAA" type="revolute">
    <origin xyz="-0.2635 -0.12291 0" rpy="0 0 0" />
    <parent link="base" />
    <child link="HR_SHOULDER" />
    <axis xyz="1 0 0" />
    <dynamics damping="0.7" friction="0.0" />
    <limit lower="-3.14" upper="3.14" effort="85.0" velocity="16.75" />
  </joint>

  <link name="HR_UPPER_LEG">
    <inertial>
      <origin xyz="0.000003 -0.025470 -0.134787" rpy="0 0 0" />
      <mass value="1.315" />
      <inertia ixx="0.011053" ixy="0.000000" ixz="0.000013" iyy="0.011463" iyz="-0.000105" izz="0.001146" />
    </inertial>
    <visual>
      <origin xyz="0 0 0" rpy="0 0 0" />
      <geometry><mesh filename="package://quadruped_description/meshes/HR_UPPER_LEG.dae" /></geometry>
      <material name="black1"/>
    </visual>
    <collision>
      <origin xyz="0 -0.028 -0.1005" rpy="0 0 0" />
      <geometry><box size="0.08 0.05 0.26" /></geometry>
    </collision>
  </link>
  <joint name="HR_HFE" type="revolute">
    <origin xyz="-0.053259 -0.061836 -0.0001687" rpy="0 0 0" />
    <parent link="HR_SHOULDER" />
    <child link="HR_UPPER_LEG" />
    <axis xyz="0 1 0" />
    <dynamics damping="0.9" friction="0.0" />
    <limit lower="-3.14" upper="3.14" effort="85.0" velocity="16.75" />
  </joint>

  <link name="HR_LOWER_LEG">
    <inertial>
      <origin xyz="-0.040122 -0.034916 -0.027409" rpy="0 0 0" />
      <mass value="1.406" />
      <inertia ixx="0.003597" ixy="0.000009" ixz="0.000762" iyy="0.004846" iyz="0.000001" izz="0.001602" />
    </inertial>
    <visual>
      <origin xyz="0 0 0" rpy="0 0 0" />
      <geometry><mesh filename="package://quadruped_description/meshes/HR_LOWER_LEG.dae" /></geometry>
      <material name="black2"/>
    </visual>
    <collision>
      <origin xyz="0 -0.045 -0.1232" rpy="0 0 0" />
      <geometry><box size="0.06 0.05 0.35" /></geometry>
    </collision>
  </link>
  <joint name="HR_KFE" type="revolute">
    <origin xyz="0 -0.0465 -0.201" rpy="0 0 0" />
    <parent link="HR_UPPER_LEG" />
    <child link="HR_LOWER_LEG" />
    <axis xyz="0 1 0" />
    <dynamics damping="0.9" friction="0.0" />
    <limit lower="-3.14" upper="3.14" effort="80.0" velocity="23.04" />
  </joint>

  <link name="HR_SHANK">
    <inertial>
      <origin xyz="-0.040122 -0.034916 -0.027409" rpy="0 0 0" />
      <mass value="0.734" />
      <inertia ixx="0.003597" ixy="0.000009" ixz="0.000762" iyy="0.004846" iyz="0.000001" izz="0.001602" />
    </inertial>
    <visual>
      <origin xyz="0 0 0" rpy="0 0 0" />
      <geometry><mesh filename="package://quadruped_description/meshes/HR_SHANK.dae" /></geometry>
      <material name="black3"/>
    </visual>
    <collision>
      <origin xyz="-0.0772 -0.035 -0.045" rpy="0 0 0" />
      <geometry><cylinder length="0.21" radius="0.02"/></geometry>
    </collision>
  </link>
  <joint name="HR_AFE" type="revolute">
    <origin xyz="0 -0.0635 -0.2465" rpy="0 0 0" />
    <parent link="HR_LOWER_LEG" />
    <child link="HR_SHANK" />
    <axis xyz="0 1 0" />
    <dynamics damping="0.9" friction="0.0" />
    <limit lower="-3.14" upper="3.14" effort="80.0" velocity="23.04" />
  </joint>

  <link name="HR_FOOT">
    <inertial>
      <origin xyz="0.037082 0.000084 0.116555" rpy="0 0 0" />
      <mass value="0.01" />
      <inertia ixx="0.003597" ixy="0.000009" ixz="0.000762" iyy="0.004846" iyz="0.000001" izz="0.001602" />
    </inertial>
    <visual>
      <origin xyz="0 0 0" rpy="0 0 0" />
      <geometry><mesh filename="package://quadruped_description/meshes/HR_FOOT.dae" /></geometry>
      <material name="red"/>
    </visual>
    <collision>
      <origin xyz="0 0 -0.02" rpy="0 0 0" />
      <geometry><sphere radius="0.0267" /></geometry>
    </collision>
  </link>
  <joint name="HR_FOOT_JOINT" type="fixed">
    <origin xyz="-0.077203 -0.035 -0.14396" rpy="0 0 0" />
    <parent link="HR_SHANK" />
    <child link="HR_FOOT" />
  </joint>

</robot>
